Workbook
Name CASE: [1]Drivers!$B$8
Name IQ_CH: 110000
Name IQ_CQ: 5000
Name IQ_CY: 10000
Name IQ_DAILY: 500000
Name IQ_FH: 100000
Name IQ_FQ: 500
Name IQ_FY: 1000
Name IQ_LTM: 2000
Name IQ_MONTH: 15000
Name IQ_NTM: 6000
Name IQ_WEEK: 50000
Name IQ_YTD: 3000

Sheet Cover
B13: Ryan Lee
B14: Genuine Parts Company (NYSE: GPC)
B15: Recommendation: BUY
B16: Price Target: $181.41
B17: Implied Upside: 31.30%
B18: 45931

Sheet Summary
B2: Case (adjustable) | C2: 1 | D2: 1 (Base) | E2: 2 (Upside) | F2: 3 (Downside)
B4: Dashboard Summary
B5: $ in millions, unless otherwise stated
K6: Projected
B7: Trading Statistics | E7: 45931 | G7: Valuation Overview (FY End: 12/31) | H7: =YEAR($E$7)-3 -> 2022 | I7: =YEAR($E$7)-2 -> 2023 | J7: =YEAR($E$7)-1 -> 2024 | K7: =YEAR($E$7)&"E" -> 2025E | L7: =YEAR($E$7)+1&"E" -> 2026E | M7: =YEAR($E$7)+2&"E" -> 2027E | N7: =YEAR($E$7)+3&"E" -> 2028E | O7: =YEAR($E$7)+4&"E" -> 2029E | P7: =YEAR($E$7)+5&"E" -> 2030E
B8: Share price ($) | E8: 138.17 | G8: Revenue | H8: ='Financial Statements'!C9 -> 22095.97 | I8: ='Financial Statements'!D9 -> 23090.61 | J8: ='Financial Statements'!E9 -> 23486.569 | K8: ='Financial Statements'!F9 -> 24352.186 | L8: ='Financial Statements'!G9 -> 25289.482 | M8: ='Financial Statements'!H9 -> 26304.085 | N8: ='Financial Statements'!I9 -> 27402.221 | O8: ='Financial Statements'!J9 -> 28590.773 | P8: ='Financial Statements'!K9 -> 29877.358
B9: Shares outstanding (M) | G9: Consensus | K9: 24060.9 | L9: 25233.13 | M9: 26353.03 | N9: 27428.5 | O9: 27942 | P9: 28906
B10: Market cap | E10: =Comps!C10 -> 19279.583 | G10: EBITDA | H10: =H8+'Financial Statements'!C11+'Financial Statements'!C13+'Financial Statements'!C15 -> 1962.015 | I10: =I8+'Financial Statements'!D11+'Financial Statements'!D13+'Financial Statements'!D15 -> 2097.582 | J10: =J8+'Financial Statements'!E11+'Financial Statements'!E13+'Financial Statements'!E15 -> 1850.714 | K10: =K8+'Financial Statements'!F11+'Financial Statements'!F13+'Financial Statements'!F15 -> 1923.8227 | L10: =L8+'Financial Statements'!G11+'Financial Statements'!G13+'Financial Statements'!G15 -> 2124.3164 | M10: =M8+'Financial Statements'!H11+'Financial Statements'!H13+'Financial Statements'!H15 -> 2341.0635 | N10: =N8+'Financial Statements'!I11+'Financial Statements'!I13+'Financial Statements'!I15 -> 2575.8088 | O10: =O8+'Financial Statements'!J11+'Financial Statements'!J13+'Financial Statements'!J15 -> 2830.4866 | P10: =P8+'Financial Statements'!K11+'Financial Statements'!K13+'Financial Statements'!K15 -> 3107.2453
B11: Net debt | E11: 3806.91 | G11: Consensus | K11: 1930.91 | L11: 2209.18 | M11: 2345.3 | N11: 2446.5 | O11: 2456 | P11: 2543
B12: Enterprise Value | E12: =+E10+E11 -> 23086.493 | G12: EPS | H12: ='Financial Statements'!C24/141.47 -> 8.3600622 | I12: ='Financial Statements'!D24/140.37 -> 9.3789556 | J12: ='Financial Statements'!E24/139.21 -> 6.4943323 | K12: ='Financial Statements'!F24/140 -> 7.1412786 | L12: ='Financial Statements'!G24/140 -> 8.6291324 | M12: ='Financial Statements'!H24/140 -> 9.1979748 | N12: ='Financial Statements'!I24/140 -> 9.8139096 | O12: ='Financial Statements'!J24/140 -> 10.481582 | P12: ='Financial Statements'!K24/140 -> 11.206143
G13: Consensus | K13: 6.58 | L13: 8.36 | M13: 9.26 | N13: 10.07 | O13: 10.71 | P13: 11.4
B14: Perpetuity Growth Method | C14: Base | D14: Upside | E14: Downside | G14: FCF ($) | H14: 821.2 | I14: 703.97 | J14: 447.97 | K14: =DCF!C25 -> 1214.122 | L14: =DCF!D25 -> 950.67528 | M14: =DCF!E25 -> 977.46721 | N14: =DCF!F25 -> 1006.3572 | O14: =DCF!G25 -> 1037.4758 | P14: =DCF!H25 -> 1070.9661
B15: Implied Equity Value | C15: 21541.128 | D15: 26721.667 | E15: 14310.175 | G15: Diluted Shares Out | H15: 142.3 | I15: 141 | J15: 139.7 | K15: 139.2 | L15: 140 | M15: 140 | N15: 140 | O15: 140 | P15: 140
B16: Diluted Shares Outstanding | C16: 139.67 | D16: 139.67 | E16: 139.67 | G16: FCF/share | H16: =H14/H15 -> 5.7709065 | I16: =I14/I15 -> 4.992695 | J16: =J14/J15 -> 3.2066571 | K16: =K14/K15 -> 8.7221408 | L16: =L14/L15 -> 6.7905377 | M16: =M14/M15 -> 6.9819086 | N16: =N14/N15 -> 7.1882657 | O16: =O14/O15 -> 7.4105416 | P16: =P14/P15 -> 7.6497575
B17: Implied Price | C17: =C15/C16 -> 154.22874 | D17: =D15/D16 -> 191.32002 | E17: =E15/E16 -> 102.45704
G18: Revenue growth % | I18: ='Financial Statements'!D10 -> 0.045014543 | J18: ='Financial Statements'!E10 -> 0.017148053 | K18: ='Financial Statements'!F10 -> 0.036855834 | L18: ='Financial Statements'!G10 -> 0.03848917 | M18: ='Financial Statements'!H10 -> 0.040119578 | N18: ='Financial Statements'!I10 -> 0.041747734 | O18: ='Financial Statements'!J10 -> 0.043374317 | P18: ='Financial Statements'!K10 -> 0.045
B19: Exit Multiple Method | C19: Base | D19: Upside | E19: Downside | G19: Gross Profit Margin % | H19: ='Financial Statements'!C12/'Financial Statements'!C9 -> 0.35029469 | I19: ='Financial Statements'!D12/'Financial Statements'!D9 -> 0.3590495 | J19: ='Financial Statements'!E12/'Financial Statements'!E9 -> 0.36291444 | K19: ='Financial Statements'!F12/'Financial Statements'!F9 -> 0.365 | L19: ='Financial Statements'!G12/'Financial Statements'!G9 -> 0.3675 | M19: ='Financial Statements'!H12/'Financial Statements'!H9 -> 0.37 | N19: ='Financial Statements'!I12/'Financial Statements'!I9 -> 0.3725 | O19: ='Financial Statements'!J12/'Financial Statements'!J9 -> 0.375 | P19: ='Financial Statements'!K12/'Financial Statements'!K9 -> 0.3775
B20: Implied Equity Value | C20: 29135.147 | D20: 34919.896 | E20: 21137.199 | G20: EBITDA Margin % | H20: =H10/H8 -> 0.088795151 | I20: =I10/I8 -> 0.090841342 | J20: =J10/J8 -> 0.078798823 | K20: =K10/K8 -> 0.079 | L20: =L10/L8 -> 0.084 | M20: =M10/M8 -> 0.089 | N20: =N10/N8 -> 0.094 | O20: =O10/O8 -> 0.099 | P20: =P10/P8 -> 0.104
B21: Diluted Shares Outstanding | C21: 139.67 | D21: 139.67 | E21: 139.67
B22: Implied Price | C22: =C20/C21 -> 208.59989 | D22: =D20/D21 -> 250.01716 | E22: =E20/E21 -> 151.33672 | G22: EV/EBITDA | H22: =$E$12/H10 -> 11.766726 | I22: =$E$12/I10 -> 11.006241 | J22: =$E$12/J10 -> 12.474371 | K22: =$E$12/K10 -> 12.000323 | L22: =$E$12/L10 -> 10.867728 | M22: =$E$12/M10 -> 9.8615405 | N22: =$E$12/N10 -> 8.9628133 | O22: =$E$12/O10 -> 8.156369 | P22: =$E$12/P10 -> 7.4298908
G23: P/EPS | H23: =$E$8/H12 -> 16.527389 | I23: =$E$8/I12 -> 14.731917 | J23: =$E$8/J12 -> 21.275474 | K23: =$E$8/K12 -> 19.348076 | L23: =$E$8/L12 -> 16.012039 | M23: =$E$8/M12 -> 15.021785 | N23: =$E$8/N12 -> 14.078997 | O23: =$E$8/O12 -> 13.182171 | P23: =$E$8/P12 -> 12.329844
C24: Base | D24: Upside | E24: Downside | G24: FCF Yield %
B25: Blended Share Price | C25: =C17*0.5+C22*0.5 -> 181.41431 | D25: =D17*0.5+D22*0.5 -> 220.66859 | E25: =E17*0.5+E22*0.5 -> 126.89688
G26: Net debt | H26: 2675.36 | I26: 2804.22 | J26: 3804.35 | K26: 3806.91 | L26: 4045.42 | M26: 3857.94 | N26: 3269 | O26: 3055 | P26: 3113
B27: Upside / Downside | C27: =(C25-$E$8)/$E$8 -> 0.31297905 | D27: =(D25-$E$8)/$E$8 -> 0.59708032 | E27: =(E25-$E$8)/$E$8 -> -0.081588777 | G27: Net debt / EBITDA | H27: =H26/H10 -> 1.3635778 | I27: =I26/I10 -> 1.3368822 | J27: =J26/J10 -> 2.0556121 | K27: =K26/K10 -> 1.9788258 | L27: =L26/L10 -> 1.9043396 | M27: =M26/M10 -> 1.6479433 | N27: =N26/N10 -> 1.269116 | O27: =O26/O10 -> 1.0793197 | P27: =P26/P10 -> 1.001852

Sheet Financial Statements
B2: Active Case: | C2: =Summary!C2 -> 1
B3: $ in millions | F3: Projected Years
C5: =Summary!H7 -> 2022 | D5: =Summary!I7 -> 2023 | E5: =Summary!J7 -> 2024 | F5: =Summary!K7 -> 2025E | G5: =Summary!L7 -> 2026E | H5: =Summary!M7 -> 2027E | I5: =Summary!N7 -> 2028E | J5: =Summary!O7 -> 2029E | K5: =Summary!P7 -> 2030E
B8: INCOME STATEMENT
B9: Total Revenue | C9: 22095.97 | D9: 23090.61 | E9: 23486.569 | F9: ='Revenue Build'!F7 -> 24352.186 | G9: ='Revenue Build'!G7 -> 25289.482 | H9: ='Revenue Build'!H7 -> 26304.085 | I9: ='Revenue Build'!I7 -> 27402.221 | J9: ='Revenue Build'!J7 -> 28590.773 | K9: ='Revenue Build'!K7 -> 29877.358
B10: % Growth | D10: =(D9-C9)/C9 -> 0.045014543 | E10: =(E9-D9)/D9 -> 0.017148053 | F10: =(F9-E9)/E9 -> 0.036855834 | G10: =(G9-F9)/F9 -> 0.03848917 | H10: =(H9-G9)/G9 -> 0.040119578 | I10: =(I9-H9)/H9 -> 0.041747734 | J10: =(J9-I9)/I9 -> 0.043374317 | K10: =(K9-J9)/J9 -> 0.045
B11: Cost of Goods Sold | C11: -14355.869 | D11: -14799.938 | E11: -14962.954 | F11: =-Assumptions!F8 -> -15463.638 | G11: =-Assumptions!G8 -> -15995.597 | H11: =-Assumptions!H8 -> -16571.573 | I11: =-Assumptions!I8 -> -17194.894 | J11: =-Assumptions!J8 -> -17869.233 | K11: =-Assumptions!K8 -> -18598.655
B12: Gross Profit | C12: =C9+C11 -> 7740.101 | D12: =D9+D11 -> 8290.672 | E12: =E9+E11 -> 8523.615 | F12: =F9+F11 -> 8888.5479 | G12: =G9+G11 -> 9293.8845 | H12: =H9+H11 -> 9732.5114 | I12: =I9+I11 -> 10207.327 | J12: =J9+J11 -> 10721.54 | K12: =K9+K11 -> 11278.703
B13: Selling General & Administrative Expense | C13: -5758.295 | D13: -6167.143 | E13: -6642.9 | F13: =-Assumptions!F14 -> -6940.373 | G13: =-Assumptions!G14 -> -7144.2785 | H13: =-Assumptions!H14 -> -7365.1438 | I13: =-Assumptions!I14 -> -7604.1163 | J13: =-Assumptions!J14 -> -7862.4627 | K13: =-Assumptions!K14 -> -8141.5801
B14: Depreciation and Amortization | C14: -347.819 | D14: -350.529 | E14: -407.978 | F14: =-Assumptions!F20 -> -426.16326 | G14: =-Assumptions!G20 -> -531.07911 | H14: =-Assumptions!H20 -> -644.45008 | I14: =-Assumptions!I20 -> -767.26218 | J14: =-Assumptions!J20 -> -900.60936 | K14: =-Assumptions!K20 -> -1045.7075
B15: Provision for Bad Debt | C15: -19.791 | D15: -25.947 | E15: -30.001 | F15: =-Assumptions!F26 -> -24.352186 | G15: =-Assumptions!G26 -> -25.289482 | H15: =-Assumptions!H26 -> -26.304085 | I15: =-Assumptions!I26 -> -27.402221 | J15: =-Assumptions!J26 -> -28.590773 | K15: =-Assumptions!K26 -> -29.877358
B16: Restructuring and Other Costs | C16: 0 | D16: 0 | E16: -213.52 | F16: =-Assumptions!F32 -> -170.4653 | G16: =-Assumptions!G32 -> 0 | H16: =-Assumptions!H32 -> 0 | I16: =-Assumptions!I32 -> 0 | J16: =-Assumptions!J32 -> 0 | K16: =-Assumptions!K32 -> 0
B17: Total Operating Expenses | C17: =SUM(C13:C16) -> -6125.905 | D17: =SUM(D13:D16) -> -6543.619 | E17: =SUM(E13:E16) -> -7294.399 | F17: =SUM(F13:F16) -> -7561.3538 | G17: =SUM(G13:G16) -> -7700.6471 | H17: =SUM(H13:H16) -> -8035.8979 | I17: =SUM(I13:I16) -> -8398.7807 | J17: =SUM(J13:J16) -> -8791.6628 | K17: =SUM(K13:K16) -> -9217.165
B18: Operating Income | C18: =C12+C17 -> 1614.196 | D18: =D12+D17 -> 1747.053 | E18: =E12+E17 -> 1229.216 | F18: =F12+F17 -> 1327.1941 | G18: =G12+G17 -> 1593.2373 | H18: =H12+H17 -> 1696.6135 | I18: =I12+I17 -> 1808.5466 | J18: =J12+J17 -> 1929.8772 | K18: =K12+K17 -> 2061.5377
B19: Interest Expense, net | C19: -73.887 | D19: -64.469 | E19: -96.827 | F19: =-Assumptions!F38 -> -97.408744 | G19: =-Assumptions!G38 -> -101.15793 | H19: =-Assumptions!H38 -> -105.21634 | I19: =-Assumptions!I38 -> -109.60888 | J19: =-Assumptions!J38 -> -114.36309 | K19: =-Assumptions!K38 -> -119.50943
B20: Other Income | C20: 32.29 | D20: 59.764 | E20: 43.579 | F20: =Assumptions!F44 -> 48.704372 | G20: =Assumptions!G44 -> 50.578963 | H20: =Assumptions!H44 -> 52.60817 | I20: =Assumptions!I44 -> 54.804442 | J20: =Assumptions!J44 -> 57.181547 | K20: =Assumptions!K44 -> 59.754716
B21: Total Non-Operating Expenses | C21: =C19+C20 -> -41.597 | D21: =D19+D20 -> -4.705 | E21: =E19+E20 -> -53.248 | F21: =F19+F20 -> -48.704372 | G21: =G19+G20 -> -50.578963 | H21: =H19+H20 -> -52.60817 | I21: =I19+I20 -> -54.804442 | J21: =J19+J20 -> -57.181547 | K21: =K19+K20 -> -59.754716
B22: Income Before Taxes | C22: =C18+C21 -> 1572.599 | D22: =D18+D21 -> 1742.348 | E22: =E18+E21 -> 1175.968 | F22: =F18+F21 -> 1278.4898 | G22: =G18+G21 -> 1542.6584 | H22: =H18+H21 -> 1644.0053 | I22: =I18+I21 -> 1753.7421 | J22: =J18+J21 -> 1872.6957 | K22: =K18+K21 -> 2001.783
B23: Income Taxes | C23: -389.901 | D23: -425.824 | E23: -271.892 | F23: =-Assumptions!F50 -> -278.71077 | G23: =-Assumptions!G50 -> -334.57984 | H23: =-Assumptions!H50 -> -356.28883 | I23: =-Assumptions!I50 -> -379.79478 | J23: =-Assumptions!J50 -> -405.27421 | K23: =-Assumptions!K50 -> -432.92292
B24: Net Income | C24: =C22+C23 -> 1182.698 | D24: =D22+D23 -> 1316.524 | E24: =E22+E23 -> 904.076 | F24: =F22+F23 -> 999.779 | G24: =G22+G23 -> 1208.0785 | H24: =H22+H23 -> 1287.7165 | I24: =I22+I23 -> 1373.9473 | J24: =J22+J23 -> 1467.4214 | K24: =K22+K23 -> 1568.8601
B27: BALANCE SHEET
B28: Assets:
B29: Current Assets:
B30: Cash and Cash Equivalents | C30: 653.463 | D30: 1102.007 | E30: 479.991
B31: Trade Accounts Receivable, net | C31: 2188.868 | D31: 2223.431 | E31: 2182.856
B32: Merchandise Inventories, net | C32: 4441.649 | D32: 4676.686 | E32: 5514.427
B33: Prepaid Expenses and Other Current Assets | C33: 1532.759 | D33: 1603.728 | E33: 1675.31
B34: Total Current Assets | C34: =SUM(C30:C33) -> 8816.739 | D34: =SUM(D30:D33) -> 9605.852 | E34: =SUM(E30:E33) -> 9852.584
B35: Goodwill | C35: 2588.113 | D35: 2734.681 | E35: 2897.27
B36: Other Intangible Assets, net | C36: 1812.51 | D36: 1792.913 | E36: 1799.031
B37: Property, Plant, and Equipment, net | C37: 1326.014 | D37: 1616.785 | E37: 1950.76
B38: Operating Lease Assets | C38: 1104.678 | D38: 1268.742 | E38: 1769.72
B39: Other Assets | C39: 847.325 | D39: 949.481 | E39: 1013.34
B40: Total Assets | C40: =SUM(C34:C39) -> 16495.379 | D40: =SUM(D34:D39) -> 17968.454 | E40: =SUM(E34:E39) -> 19282.705
B42: Liabilities and Equity:
B43: Current Liabilities:
B44: Trade Accounts Payable | C44: 5456.55 | D44: 5499.536 | E44: 5923.684
B45: Current Portion of Debt | C45: 252.029 | D45: 355.298 | E45: 541.705
B46: Other Current Liabilities | C46: 1851.34 | D46: 1839.64 | E46: 1925.636
B47: Dividends Payable | C47: 126.191 | D47: 132.635 | E47: 134.355
...

Sheet Revenue Build
B2: Active Case: | C2: =Summary!C2 -> 1
B3: $ in millions | F3: Projected Years
C5: =Summary!H7 -> 2022 | D5: =Summary!I7 -> 2023 | E5: =Summary!J7 -> 2024 | F5: =Summary!K7 -> 2025E | G5: =Summary!L7 -> 2026E | H5: =Summary!M7 -> 2027E | I5: =Summary!N7 -> 2028E | J5: =Summary!O7 -> 2029E | K5: =Summary!P7 -> 2030E
B7: Total Revenue | C7: =C10+C16 -> 22095.973 | D7: =D10+D16 -> 23090.61 | E7: =E10+E16 -> 23486.569 | F7: =F10+F16 -> 24352.186 | G7: =G10+G16 -> 25289.482 | H7: =H10+H16 -> 26304.085 | I7: =I10+I16 -> 27402.221 | J7: =J10+J16 -> 28590.773 | K7: =K10+K16 -> 29877.358
B8: % Growth | D8: =(D7-C7)/C7 -> 0.045014401 | E8: =(E7-D7)/D7 -> 0.017148053 | F8: =(F7-E7)/E7 -> 0.036855834 | G8: =(G7-F7)/F7 -> 0.03848917 | H8: =(H7-G7)/G7 -> 0.040119578 | I8: =(I7-H7)/H7 -> 0.041747734 | J8: =(J7-I7)/I7 -> 0.043374317 | K8: =(K7-J7)/J7 -> 0.045
B10: Automotive | C10: 13666.634 | D10: 14246.783 | E10: 14769.133 | F10: =E10*(1+F11) -> 15286.053 | G10: =F10*(1+G11) -> 15851.637 | H10: =G10*(1+H11) -> 16469.85 | I10: =H10*(1+I11) -> 17145.114 | J10: =I10*(1+J11) -> 17882.354 | K10: =J10*(1+K11) -> 18687.06
B11: % Growth | D11: =(D10-C10)/C10 -> 0.042450028 | E11: =(E10-D10)/D10 -> 0.036664418 | F11: =OFFSET(F11, $C$2,0) -> 0.035 | G11: =OFFSET(G11, $C$2,0) -> 0.037 | H11: =OFFSET(H11, $C$2,0) -> 0.039 | I11: =OFFSET(I11, $C$2,0) -> 0.041 | J11: =OFFSET(J11, $C$2,0) -> 0.043 | K11: =OFFSET(K11, $C$2,0) -> 0.045
B12: Base | F12: 0.035 | G12: =F12+0.002 -> 0.037 | H12: =G12+0.002 -> 0.039 | I12: =H12+0.002 -> 0.041 | J12: =I12+0.002 -> 0.043 | K12: =J12+0.002 -> 0.045
B13: Upside | F13: 0.045 | G13: =F13+0.002 -> 0.047 | H13: =G13+0.002 -> 0.049 | I13: =H13+0.002 -> 0.051 | J13: =I13+0.002 -> 0.053 | K13: =J13+0.002 -> 0.055
B14: Downside | F14: 0.025 | G14: =F14-0.002 -> 0.023 | H14: =G14-0.002 -> 0.021 | I14: =H14-0.002 -> 0.019 | J14: =I14-0.002 -> 0.017 | K14: =J14-0.002 -> 0.015
B16: Industrials | C16: 8429.339 | D16: 8843.827 | E16: 8717.436 | F16: =E16*(1+F17) -> 9066.1334 | G16: =F16*(1+G17) -> 9437.8449 | H16: =G16*(1+H17) -> 9834.2344 | I16: =H16*(1+I17) -> 10257.106 | J16: =I16*(1+J17) -> 10708.419 | K16: =J16*(1+K17) -> 11190.298
B17: % Growth | D17: =(D16-C16)/C16 -> 0.049172064 | E17: =(E16-D16)/D16 -> -0.014291437 | F17: =OFFSET(F17,$C$2,0) -> 0.04 | G17: =OFFSET(G17,$C$2,0) -> 0.041 | H17: =OFFSET(H17,$C$2,0) -> 0.042 | I17: =OFFSET(I17,$C$2,0) -> 0.043 | J17: =OFFSET(J17,$C$2,0) -> 0.044 | K17: =OFFSET(K17,$C$2,0) -> 0.045
B18: Base | F18: 0.04 | G18: =F18+0.001 -> 0.041 | H18: =G18+0.001 -> 0.042 | I18: =H18+0.001 -> 0.043 | J18: =I18+0.001 -> 0.044 | K18: =J18+0.001 -> 0.045
B19: Upside | F19: 0.045 | G19: =F19+0.001 -> 0.046 | H19: =G19+0.001 -> 0.047 | I19: =H19+0.001 -> 0.048 | J19: =I19+0.001 -> 0.049 | K19: =J19+0.001 -> 0.05
B20: Downside | F20: 0.03 | G20: =F20-0.001 -> 0.029 | H20: =G20-0.001 -> 0.028 | I20: =H20-0.001 -> 0.027 | J20: =I20-0.001 -> 0.026 | K20: =J20-0.001 -> 0.025
B22: # of Locations Automotive
B23: Total | C23: =C26+C32 -> 9632 | D23: =D26+D32 -> 9805 | E23: =E26+E32 -> 9846 | F23: =F26+F32 -> 10047.5 | G23: =G26+G32 -> 10305.947 | H23: =H26+H32 -> 10625.806 | I23: =I26+I32 -> 11012.504 | J23: =J26+J32 -> 11472.554 | K23: =K26+K32 -> 12013.701
B24: % Growth | D24: =(D23-C23)/C23 -> 0.017960963 | E24: =(E23-D23)/D23 -> 0.00418154 | F24: =(F23-E23)/E23 -> 0.020465164 | G24: =(G23-F23)/F23 -> 0.025722473 | H24: =(H23-G23)/G23 -> 0.031036382 | I24: =(I23-H23)/H23 -> 0.036392396 | J24: =(J23-I23)/I23 -> 0.041775181 | K24: =(K23-J23)/J23 -> 0.047168896
B26: Company-Owned Stores | C26: 2953 | D26: 3146 | E26: 3622 | F26: =E26*(1+F27) -> 3947.98 | G26: =F26*(1+G27) -> 4313.1682 | H26: =G26*(1+H27) -> 4722.9191 | I26: =H26*(1+I27) -> 5183.4037 | J26: =I26*(1+J27) -> 5701.7441 | K26: =J26*(1+K27) -> 6286.1729
B27: % Growth | D27: =(D26-C26)/C26 -> 0.065357264 | E27: =(E26-D26)/D26 -> 0.15130324 | F27: =OFFSET(F27,$C$2,0) -> 0.09 | G27: =OFFSET(G27,$C$2,0) -> 0.0925 | H27: =OFFSET(H27,$C$2,0) -> 0.095 | I27: =OFFSET(I27,$C$2,0) -> 0.0975 | J27: =OFFSET(J27,$C$2,0) -> 0.1 | K27: =OFFSET(K27,$C$2,0) -> 0.1025
B28: Base | F28: 0.09 | G28: =F28+0.0025 -> 0.0925 | H28: =G28+0.0025 -> 0.095 | I28: =H28+0.0025 -> 0.0975 | J28: =I28+0.0025 -> 0.1 | K28: =J28+0.0025 -> 0.1025
B29: Upside | F29: 0.1 | G29: =F29+0.0025 -> 0.1025 | H29: =G29+0.0025 -> 0.105 | I29: =H29+0.0025 -> 0.1075 | J29: =I29+0.0025 -> 0.11 | K29: =J29+0.0025 -> 0.1125
B30: Downside | F30: 0.08 | G30: =F30-0.0025 -> 0.0775 | H30: =G30-0.0025 -> 0.075 | I30: =H30-0.0025 -> 0.0725 | J30: =I30-0.0025 -> 0.07 | K30: =J30-0.0025 -> 0.0675
B32: Independently-Owned Stores | C32: 6679 | D32: 6659 | E32: 6224 | F32: =E32*(1+F33) -> 6099.52 | G32: =F32*(1+G33) -> 5992.7784 | H32: =G32*(1+H33) -> 5902.8867 | I32: =H32*(1+I33) -> 5829.1006 | J32: =I32*(1+J33) -> 5770.8096 | K32: =J32*(1+K33) -> 5727.5286
B33: % Growth | D33: =(D32-C32)/C32 -> -0.0029944602 | E33: =(E32-D32)/D32 -> -0.065325124 | F33: =OFFSET(F33,$C$2,0) -> -0.02 | G33: =OFFSET(G33,$C$2,0) -> -0.0175 | H33: =OFFSET(H33,$C$2,0) -> -0.015 | I33: =OFFSET(I33,$C$2,0) -> -0.0125 | J33: =OFFSET(J33,$C$2,0) -> -0.01 | K33: =OFFSET(K33,$C$2,0) -> -0.0075
B34: Base | F34: -0.02 | G34: =F34+0.0025 -> -0.0175 | H34: =G34+0.0025 -> -0.015 | I34: =H34+0.0025 -> -0.0125 | J34: =I34+0.0025 -> -0.01 | K34: =J34+0.0025 -> -0.0075
B35: Upside | F35: -0.01 | G35: =F35+0.0025 -> -0.0075 | H35: =G35+0.0025 -> -0.005 | I35: =H35+0.0025 -> -0.0025 | J35: =I35+0.0025 -> 0 | K35: =J35+0.0025 -> 0.0025
B36: Downside | F36: -0.03 | G36: =F36+0.0025 -> -0.0275 | H36: =G36+0.0025 -> -0.025 | I36: =H36+0.0025 -> -0.0225 | J36: =I36+0.0025 -> -0.02 | K36: =J36+0.0025 -> -0.0175
B38: # of Locations Industrials
B39: Total | C39: =C42+C48 -> 766 | D39: =D42+D48 -> 723 | E39: =E42+E48 -> 755 | F39: =F42+F48 -> 778.2 | G39: =G42+G48 -> 802.3824 | H39: =H42+H48 -> 827.5338 | I39: =I42+I48 -> 853.62824 | J39: =J42+J48 -> 880.62632 | K39: =K42+K48 -> 908.47454
B40: % Growth | D40: =(D39-C39)/C39 -> -0.05613577 | E40: =(E39-D39)/D39 -> 0.044260028 | F40: =(F39-E39)/E39 -> 0.030728477 | G40: =(G39-F39)/F39 -> 0.031074788 | H40: =(H39-G39)/G39 -> 0.031345902 | I40: =(I39-H39)/H39 -> 0.031532782 | J40: =(J39-I39)/I39 -> 0.031627447 | K40: =(K39-J39)/J39 -> 0.031623193
B42: Branches | C42: 697 | D42: 653 | E42: 674 | F42: =E42*(1+F43) -> 687.48 | G42: =F42*(1+G43) -> 701.2296 | H42: =G42*(1+H43) -> 715.25419 | I42: =H42*(1+I43) -> 729.55928 | J42: =I42*(1+J43) -> 744.15046 | K42: =J42*(1+K43) -> 759.03347
B43: % Growth | D43: =(D42-C42)/C42 -> -0.06312769 | E43: =(E42-D42)/D42 -> 0.032159265 | F43: =OFFSET(F43,$C$2,0) -> 0.02 | G43: =OFFSET(G43,$C$2,0) -> 0.02 | H43: =OFFSET(H43,$C$2,0) -> 0.02 | I43: =OFFSET(I43,$C$2,0) -> 0.02 | J43: =OFFSET(J43,$C$2,0) -> 0.02 | K43: =OFFSET(K43,$C$2,0) -> 0.02
B44: Base | F44: 0.02 | G44: 0.02 | H44: 0.02 | I44: 0.02 | J44: 0.02 | K44: 0.02
B45: Upside | F45: 0.03 | G45: 0.03 | H45: 0.03 | I45: 0.03 | J45: 0.03 | K45: 0.03
B46: Downside | F46: 0.01 | G46: 0.01 | H46: 0.01 | I46: 0.01 | J46: 0.01 | K46: 0.01
B48: Service Centers | C48: 69 | D48: 70 | E48: 81 | F48: =E48*(1+F49) -> 90.72 | G48: =F48*(1+G49) -> 101.1528 | H48: =G48*(1+H49) -> 112.27961 | I48: =H48*(1+I49) -> 124.06897 | J48: =I48*(1+J49) -> 136.47586 | K48: =J48*(1+K49) -> 149.44107
B49: % Growth | D49: =(D48-C48)/C48 -> 0.014492754 | E49: =(E48-D48)/D48 -> 0.15714286 | F49: =OFFSET(F49,$C$2,0) -> 0.12 | G49: =OFFSET(G49,$C$2,0) -> 0.115 | H49: =OFFSET(H49,$C$2,0) -> 0.11 | I49: =OFFSET(I49,$C$2,0) -> 0.105 | J49: =OFFSET(J49,$C$2,0) -> 0.1 | K49: =OFFSET(K49,$C$2,0) -> 0.095
B50: Base | F50: 0.12 | G50: =F50-0.005 -> 0.115 | H50: =G50-0.005 -> 0.11 | I50: =H50-0.005 -> 0.105 | J50: =I50-0.005 -> 0.1 | K50: =J50-0.005 -> 0.095
B51: Upside | F51: 0.13 | G51: =F51-0.005 -> 0.125 | H51: =G51-0.005 -> 0.12 | I51: =H51-0.005 -> 0.115 | J51: =I51-0.005 -> 0.11 | K51: =J51-0.005 -> 0.105
...

Sheet Assumptions
B2: Active Case: | C2: =Summary!C2 -> 1
B3: $ in millions | F3: Projected Years
C5: =Summary!H7 -> 2022 | D5: =Summary!I7 -> 2023 | E5: =Summary!J7 -> 2024 | F5: =Summary!K7 -> 2025E | G5: =Summary!L7 -> 2026E | H5: =Summary!M7 -> 2027E | I5: =Summary!N7 -> 2028E | J5: =Summary!O7 -> 2029E | K5: =Summary!P7 -> 2030E
B7: Income Statement
B8: Cost of Goods Sold | C8: ='Financial Statements'!C11*-1 -> 14355.869 | D8: ='Financial Statements'!D11*-1 -> 14799.938 | E8: ='Financial Statements'!E11*-1 -> 14962.954 | F8: =F9*'Financial Statements'!F$9 -> 15463.638 | G8: =G9*'Financial Statements'!G$9 -> 15995.597 | H8: =H9*'Financial Statements'!H$9 -> 16571.573 | I8: =I9*'Financial Statements'!I$9 -> 17194.894 | J8: =J9*'Financial Statements'!J$9 -> 17869.233 | K8: =K9*'Financial Statements'!K$9 -> 18598.655
B9: % of Revenue | C9: =C8/'Financial Statements'!C$9 -> 0.64970531 | D9: =D8/'Financial Statements'!D$9 -> 0.6409505 | E9: =E8/'Financial Statements'!E$9 -> 0.63708556 | F9: =OFFSET(F9,$C$2,0) -> 0.635 | G9: =OFFSET(G9,$C$2,0) -> 0.6325 | H9: =OFFSET(H9,$C$2,0) -> 0.63 | I9: =OFFSET(I9,$C$2,0) -> 0.6275 | J9: =OFFSET(J9,$C$2,0) -> 0.625 | K9: =OFFSET(K9,$C$2,0) -> 0.6225
B10: Base | F10: 0.635 | G10: =F10-0.0025 -> 0.6325 | H10: =G10-0.0025 -> 0.63 | I10: =H10-0.0025 -> 0.6275 | J10: =I10-0.0025 -> 0.625 | K10: =J10-0.0025 -> 0.6225
B11: Upside | F11: =F10-0.01 -> 0.625 | G11: =F11-0.0025 -> 0.6225 | H11: =G11-0.0025 -> 0.62 | I11: =H11-0.0025 -> 0.6175 | J11: =I11-0.0025 -> 0.615 | K11: =J11-0.0025 -> 0.6125
B12: Downside | F12: =F10+0.01 -> 0.645 | G12: =F12-0.0025 -> 0.6425 | H12: =G12-0.0025 -> 0.64 | I12: =H12-0.0025 -> 0.6375 | J12: =I12-0.0025 -> 0.635 | K12: =J12-0.0025 -> 0.6325
B14: Selling, General, and Administrative Expense | C14: ='Financial Statements'!C13*-1 -> 5758.295 | D14: ='Financial Statements'!D13*-1 -> 6167.143 | E14: ='Financial Statements'!E13*-1 -> 6642.9 | F14: =F15*'Financial Statements'!F$9 -> 6940.373 | G14: =G15*'Financial Statements'!G$9 -> 7144.2785 | H14: =H15*'Financial Statements'!H$9 -> 7365.1438 | I14: =I15*'Financial Statements'!I$9 -> 7604.1163 | J14: =J15*'Financial Statements'!J$9 -> 7862.4627 | K14: =K15*'Financial Statements'!K$9 -> 8141.5801
B15: % of Revenue | C15: =C14/'Financial Statements'!C$9 -> 0.26060386 | D15: =D14/'Financial Statements'!D$9 -> 0.26708446 | E15: =E14/'Financial Statements'!E$9 -> 0.28283825 | F15: =OFFSET(F15,$C$2,0) -> 0.285 | G15: =OFFSET(G15,$C$2,0) -> 0.2825 | H15: =OFFSET(H15,$C$2,0) -> 0.28 | I15: =OFFSET(I15,$C$2,0) -> 0.2775 | J15: =OFFSET(J15,$C$2,0) -> 0.275 | K15: =OFFSET(K15,$C$2,0) -> 0.2725
B16: Base | F16: 0.285 | G16: =F16-0.0025 -> 0.2825 | H16: =G16-0.0025 -> 0.28 | I16: =H16-0.0025 -> 0.2775 | J16: =I16-0.0025 -> 0.275 | K16: =J16-0.0025 -> 0.2725
B17: Upside | F17: =F16-0.005 -> 0.28 | G17: =F17-0.0025 -> 0.2775 | H17: =G17-0.0025 -> 0.275 | I17: =H17-0.0025 -> 0.2725 | J17: =I17-0.0025 -> 0.27 | K17: =J17-0.0025 -> 0.2675
B18: Downside | F18: =F16+0.01 -> 0.295 | G18: =F18-0.0025 -> 0.2925 | H18: =G18-0.0025 -> 0.29 | I18: =H18-0.0025 -> 0.2875 | J18: =I18-0.0025 -> 0.285 | K18: =J18-0.0025 -> 0.2825
B20: Depreciation & Amortization | C20: ='Financial Statements'!C14*-1 -> 347.819 | D20: ='Financial Statements'!D14*-1 -> 350.529 | E20: ='Financial Statements'!E14*-1 -> 407.978 | F20: =F21*F57 -> 426.16326 | G20: =G21*G57 -> 531.07911 | H20: =H21*H57 -> 644.45008 | I20: =I21*I57 -> 767.26218 | J20: =J21*J57 -> 900.60936 | K20: =K21*K57 -> 1045.7075
B21: % of Capex | C21: =C20/C57 -> 1.0241055 | D21: =D20/D57 -> 0.68372556 | E21: =E20/E57 -> 0.71910798 | F21: =OFFSET(F21,$C$2,0) -> 0.7 | G21: =OFFSET(G21,$C$2,0) -> 0.7 | H21: =OFFSET(H21,$C$2,0) -> 0.7 | I21: =OFFSET(I21,$C$2,0) -> 0.7 | J21: =OFFSET(J21,$C$2,0) -> 0.7 | K21: =OFFSET(K21,$C$2,0) -> 0.7
B22: Base | F22: 0.7 | G22: 0.7 | H22: 0.7 | I22: 0.7 | J22: 0.7 | K22: 0.7
B23: Upside | F23: =F22-0.005 -> 0.695 | G23: =G22-0.005 -> 0.695 | H23: =H22-0.005 -> 0.695 | I23: =I22-0.005 -> 0.695 | J23: =J22-0.005 -> 0.695 | K23: =K22-0.005 -> 0.695
B24: Downside | F24: 0.705 | G24: 0.705 | H24: 0.705 | I24: 0.705 | J24: 0.705 | K24: 0.705
B26: Provision for Bad Debt | C26: ='Financial Statements'!C15*-1 -> 19.791 | D26: ='Financial Statements'!D15*-1 -> 25.947 | E26: ='Financial Statements'!E15*-1 -> 30.001 | F26: =F27*'Financial Statements'!F$9 -> 24.352186 | G26: =G27*'Financial Statements'!G$9 -> 25.289482 | H26: =H27*'Financial Statements'!H$9 -> 26.304085 | I26: =I27*'Financial Statements'!I$9 -> 27.402221 | J26: =J27*'Financial Statements'!J$9 -> 28.590773 | K26: =K27*'Financial Statements'!K$9 -> 29.877358
B27: % of Revenue | C27: =C26/'Financial Statements'!C$9 -> 0.00089568369 | D27: =D26/'Financial Statements'!D$9 -> 0.0011237035 | E27: =E26/'Financial Statements'!E$9 -> 0.0012773684 | F27: =OFFSET(F27,$C$2,0) -> 0.001 | G27: =OFFSET(G27,$C$2,0) -> 0.001 | H27: =OFFSET(H27,$C$2,0) -> 0.001 | I27: =OFFSET(I27,$C$2,0) -> 0.001 | J27: =OFFSET(J27,$C$2,0) -> 0.001 | K27: =OFFSET(K27,$C$2,0) -> 0.001
B28: Base | F28: 0.001 | G28: 0.001 | H28: 0.001 | I28: 0.001 | J28: 0.001 | K28: 0.001
B29: Upside | F29: 0.001 | G29: 0.001 | H29: 0.001 | I29: 0.001 | J29: 0.001 | K29: 0.001
B30: Downside | F30: 0.001 | G30: 0.001 | H30: 0.001 | I30: 0.001 | J30: 0.001 | K30: 0.001
B32: Restructuring and Other Costs | C32: ='Financial Statements'!C16*-1 -> 0 | D32: ='Financial Statements'!D16*-1 -> 0 | E32: ='Financial Statements'!E16*-1 -> 213.52 | F32: =F33*'Financial Statements'!F$9 -> 170.4653 | G32: =G33*'Financial Statements'!G$9 -> 0 | H32: =H33*'Financial Statements'!H$9 -> 0 | I32: =I33*'Financial Statements'!I$9 -> 0 | J32: =J33*'Financial Statements'!J$9 -> 0 | K32: =K33*'Financial Statements'!K$9 -> 0
B33: % of Revenue | C33: =C32/'Financial Statements'!C$9 -> 0 | D33: =D32/'Financial Statements'!D$9 -> 0 | E33: =E32/'Financial Statements'!E$9 -> 0.0090911533 | F33: =OFFSET(F33,$C$2,0) -> 0.007 | G33: =OFFSET(G33,$C$2,0) -> 0 | H33: =OFFSET(H33,$C$2,0) -> 0 | I33: =OFFSET(I33,$C$2,0) -> 0 | J33: =OFFSET(J33,$C$2,0) -> 0 | K33: =OFFSET(K33,$C$2,0) -> 0
B34: Base | F34: 0.007 | G34: 0 | H34: 0 | I34: 0 | J34: 0 | K34: 0
B35: Upside | F35: 0.006 | G35: 0 | H35: 0 | I35: 0 | J35: 0 | K35: 0
B36: Downside | F36: 0.008 | G36: 0 | H36: 0 | I36: 0 | J36: 0 | K36: 0
B38: Interest Expense, net | C38: ='Financial Statements'!C19*-1 -> 73.887 | D38: ='Financial Statements'!D19*-1 -> 64.469 | E38: ='Financial Statements'!E19*-1 -> 96.827 | F38: =F39*'Financial Statements'!F$9 -> 97.408744 | G38: =G39*'Financial Statements'!G$9 -> 101.15793 | H38: =H39*'Financial Statements'!H$9 -> 105.21634 | I38: =I39*'Financial Statements'!I$9 -> 109.60888 | J38: =J39*'Financial Statements'!J$9 -> 114.36309 | K38: =K39*'Financial Statements'!K$9 -> 119.50943
B39: % of Revenue | C39: =C38/'Financial Statements'!C$9 -> 0.0033439129 | D39: =D38/'Financial Statements'!D$9 -> 0.0027920007 | E39: =E38/'Financial Statements'!E$9 -> 0.0041226541 | F39: =OFFSET(F39,$C$2,0) -> 0.004 | G39: =OFFSET(G39,$C$2,0) -> 0.004 | H39: =OFFSET(H39,$C$2,0) -> 0.004 | I39: =OFFSET(I39,$C$2,0) -> 0.004 | J39: =OFFSET(J39,$C$2,0) -> 0.004 | K39: =OFFSET(K39,$C$2,0) -> 0.004
B40: Base | F40: 0.004 | G40: 0.004 | H40: 0.004 | I40: 0.004 | J40: 0.004 | K40: 0.004
B41: Upside | F41: 0.004 | G41: 0.004 | H41: 0.004 | I41: 0.004 | J41: 0.004 | K41: 0.004
B42: Downside | F42: 0.004 | G42: 0.004 | H42: 0.004 | I42: 0.004 | J42: 0.004 | K42: 0.004
B44: Other Income | C44: ='Financial Statements'!C20 -> 32.29 | D44: ='Financial Statements'!D20 -> 59.764 | E44: ='Financial Statements'!E20 -> 43.579 | F44: =F45*'Financial Statements'!F$9 -> 48.704372 | G44: =G45*'Financial Statements'!G$9 -> 50.578963 | H44: =H45*'Financial Statements'!H$9 -> 52.60817 | I44: =I45*'Financial Statements'!I$9 -> 54.804442 | J44: =J45*'Financial Statements'!J$9 -> 57.181547 | K44: =K45*'Financial Statements'!K$9 -> 59.754716
B45: % of Revenue | C45: =C44/'Financial Statements'!C$9 -> 0.0014613525 | D45: =D44/'Financial Statements'!D$9 -> 0.0025882382 | E45: =E44/'Financial Statements'!E$9 -> 0.001855486 | F45: =OFFSET(F45,$C$2,0) -> 0.002 | G45: =OFFSET(G45,$C$2,0) -> 0.002 | H45: =OFFSET(H45,$C$2,0) -> 0.002 | I45: =OFFSET(I45,$C$2,0) -> 0.002 | J45: =OFFSET(J45,$C$2,0) -> 0.002 | K45: =OFFSET(K45,$C$2,0) -> 0.002
B46: Base | F46: 0.002 | G46: 0.002 | H46: 0.002 | I46: 0.002 | J46: 0.002 | K46: 0.002
B47: Upside | F47: 0.002 | G47: 0.002 | H47: 0.002 | I47: 0.002 | J47: 0.002 | K47: 0.002
B48: Downside | F48: 0.002 | G48: 0.002 | H48: 0.002 | I48: 0.002 | J48: 0.002 | K48: 0.002
B50: Tax Expense | C50: ='Financial Statements'!C23*-1 -> 389.901 | D50: ='Financial Statements'!D23*-1 -> 425.824 | E50: ='Financial Statements'!E23*-1 -> 271.892 | F50: =F51*'Financial Statements'!F18 -> 278.71077 | G50: =G51*'Financial Statements'!G18 -> 334.57984 | H50: =H51*'Financial Statements'!H18 -> 356.28883 | I50: =I51*'Financial Statements'!I18 -> 379.79478 | J50: =J51*'Financial Statements'!J18 -> 405.27421 | K50: =K51*'Financial Statements'!K18 -> 432.92292
...

Sheet Calculations & Schedules
B2: Active Case: | C2: =Summary!C2 -> 1
B3: $ in millions | F3: Projected Years
C5: =Summary!H7 -> 2022 | D5: =Summary!I7 -> 2023 | E5: =Summary!J7 -> 2024 | F5: =Summary!K7 -> 2025E | G5: =Summary!L7 -> 2026E | H5: =Summary!M7 -> 2027E | I5: =Summary!N7 -> 2028E | J5: =Summary!O7 -> 2029E | K5: =Summary!P7 -> 2030E
B7: Net Working Capital Calculations
B8: Trade Accounts Receivable, net | C8: =Assumptions!C63 -> 2188.868 | D8: =Assumptions!D63 -> 2223.431 | E8: =Assumptions!E63 -> 2182.856 | F8: =Assumptions!F63 -> 2191.6967 | G8: =Assumptions!G63 -> 2276.0533 | H8: =Assumptions!H63 -> 2367.3676 | I8: =Assumptions!I63 -> 2466.1999 | J8: =Assumptions!J63 -> 2573.1696 | K8: =Assumptions!K63 -> 2688.9622
B9: Merchandise Inventory, net | C9: =Assumptions!C69 -> 4441.649 | D9: =Assumptions!D69 -> 4676.686 | E9: =Assumptions!E69 -> 5514.427 | F9: =Assumptions!F69 -> 5412.2734 | G9: =Assumptions!G69 -> 5630.4502 | H9: =Assumptions!H69 -> 5866.337 | I9: =Assumptions!I69 -> 6121.3821 | J9: =Assumptions!J69 -> 6397.1855 | K9: =Assumptions!K69 -> 6695.516
B10: Prepaid Expenses and Other Current Assets | C10: =Assumptions!C75 -> 1532.759 | D10: =Assumptions!D75 -> 1603.728 | E10: =Assumptions!E75 -> 1675.31 | F10: =Assumptions!F75 -> 1704.653 | G10: =Assumptions!G75 -> 1770.2637 | H10: =Assumptions!H75 -> 1841.2859 | I10: =Assumptions!I75 -> 1918.1555 | J10: =Assumptions!J75 -> 2001.3541 | K10: =Assumptions!K75 -> 2091.4151
B11: Non-Cash Current Assets | C11: =SUM(C8:C10) -> 8163.276 | D11: =SUM(D8:D10) -> 8503.845 | E11: =SUM(E8:E10) -> 9372.593 | F11: =SUM(F8:F10) -> 9308.6231 | G11: =SUM(G8:G10) -> 9676.7672 | H11: =SUM(H8:H10) -> 10074.991 | I11: =SUM(I8:I10) -> 10505.737 | J11: =SUM(J8:J10) -> 10971.709 | K11: =SUM(K8:K10) -> 11475.893
B13: Trade Accounts Payable | C13: =Assumptions!C81 -> 5456.55 | D13: =Assumptions!D81 -> 5499.536 | E13: =Assumptions!E81 -> 5923.684 | F13: =Assumptions!F81 -> 6185.4553 | G13: =Assumptions!G81 -> 6398.2388 | H13: =Assumptions!H81 -> 6628.6294 | I13: =Assumptions!I81 -> 6877.9574 | J13: =Assumptions!J81 -> 7147.6933 | K13: =Assumptions!K81 -> 7439.4622
B14: Other Current Liabilities | C14: =Assumptions!C87 -> 1851.34 | D14: =Assumptions!D87 -> 1839.64 | E14: =Assumptions!E87 -> 1925.636 | F14: =Assumptions!F87 -> 1948.1749 | G14: =Assumptions!G87 -> 2023.1585 | H14: =Assumptions!H87 -> 2104.3268 | I14: =Assumptions!I87 -> 2192.1777 | J14: =Assumptions!J87 -> 2287.2619 | K14: =Assumptions!K87 -> 2390.1887
B15: Non-Debt Current Liabilities | C15: =C13+C14 -> 7307.89 | D15: =D13+D14 -> 7339.176 | E15: =E13+E14 -> 7849.32 | F15: =F13+F14 -> 8133.6302 | G15: =G13+G14 -> 8421.3973 | H15: =H13+H14 -> 8732.9562 | I15: =I13+I14 -> 9070.1351 | J15: =J13+J14 -> 9434.9552 | K15: =K13+K14 -> 9829.6508
B17: Net Working Capital | C17: =C11-C15 -> 855.386 | D17: =D11-D15 -> 1164.669 | E17: =E11-E15 -> 1523.273 | F17: =F11-F15 -> 1174.993 | G17: =G11-G15 -> 1255.3699 | H17: =H11-H15 -> 1342.0344 | I17: =I11-I15 -> 1435.6023 | J17: =J11-J15 -> 1536.7541 | K17: =K11-K15 -> 1646.2424
B18: % of Revenue | C18: =C17/'Revenue Build'!C7 -> 0.038712303 | D18: =D17/'Revenue Build'!D7 -> 0.050439075 | E18: =E17/'Revenue Build'!E7 -> 0.064857196 | F18: =F17/'Revenue Build'!F7 -> 0.04825 | G18: =G17/'Revenue Build'!G7 -> 0.04964 | H18: =H17/'Revenue Build'!H7 -> 0.05102 | I18: =I17/'Revenue Build'!I7 -> 0.05239 | J18: =J17/'Revenue Build'!J7 -> 0.05375 | K18: =K17/'Revenue Build'!K7 -> 0.0551
B19: Change in Net Working Capital | D19: =D17-C17 -> 309.283 | E19: =E17-D17 -> 358.604 | F19: =F17-E17 -> -348.28002 | G19: =G17-F17 -> 80.376883 | H19: =H17-G17 -> 86.664546 | I19: =I17-H17 -> 93.567938 | J19: =J17-I17 -> 101.15172 | K19: =K17-J17 -> 109.48837
B21: Property, Plant, & Equipment Schedule
B22: Beginning PP&E | C22: 1234.399 | D22: =C27 -> 1326.014 | E22: =D27 -> 1616.785 | F22: =E27 -> 1950.76 | G22: =F27 -> 2282.5585 | H22: =G27 -> 2696.0416 | I22: =H27 -> 3197.792 | J22: =I27 -> 3795.1604 | K22: =J27 -> 4496.3491
B23: Merchandise Inventory, net | C23: =-'Financial Statements'!C85 -> 339.632 | D23: =-'Financial Statements'!D85 -> 512.675 | E23: =-'Financial Statements'!E85 -> 567.339 | F23: =Assumptions!F57 -> 608.80465 | G23: =Assumptions!G57 -> 758.68445 | H23: =Assumptions!H57 -> 920.64297 | I23: =Assumptions!I57 -> 1096.0888 | J23: =Assumptions!J57 -> 1286.5848 | K23: =Assumptions!K57 -> 1493.8679
B24: Prepaid Expenses and Other Current Assets | C24: -190.382 | D24: -203.351 | E24: -264.984 | F24: =-F25*Assumptions!F20 -> -277.00612 | G24: =-G25*Assumptions!G20 -> -345.20142 | H24: =-H25*Assumptions!H20 -> -418.89255 | I24: =-I25*Assumptions!I20 -> -498.72042 | J24: =-J25*Assumptions!J20 -> -585.39608 | K24: =-K25*Assumptions!K20 -> -679.7099
B25: Depreciation as a % of Depreciation and Amortization | C25: =-C24/Assumptions!C20 -> 0.5473594 | D25: =-D24/Assumptions!D20 -> 0.58012604 | E25: =-E24/Assumptions!E20 -> 0.64950561 | F25: 0.65 | G25: 0.65 | H25: 0.65 | I25: 0.65 | J25: 0.65 | K25: 0.65
B26: Reconciliation | C26: =-(C22+C23+C24-C27) -> -57.635 | D26: =-(D22+D23+D24-D27) -> -18.553 | E26: =-(E22+E23+E24-E27) -> 31.62 | F26: 0 | G26: 0 | H26: 0 | I26: 0 | J26: 0 | K26: 0
B27: Ending PP&E | C27: ='Financial Statements'!C37 -> 1326.014 | D27: ='Financial Statements'!D37 -> 1616.785 | E27: ='Financial Statements'!E37 -> 1950.76 | F27: =F22+F23+F24 -> 2282.5585 | G27: =G22+G23+G24 -> 2696.0416 | H27: =H22+H23+H24 -> 3197.792 | I27: =I22+I23+I24 -> 3795.1604 | J27: =J22+J23+J24 -> 4496.3491 | K27: =K22+K23+K24 -> 5310.5071
B29: Retained Earnings Schedule
B30: Beginning Retained Earnings | C30: 4086.325 | D30: =C34 -> 4541.637 | E30: =D34 -> 5065.324 | F30: =E34 -> 5263.835 | G30: =F34 -> 5483.7864 | H30: =G34 -> 5746.5435 | I30: =H34 -> 6023.4025 | J30: =I34 -> 6315.3663 | K30: =J34 -> 6623.5248
B31: Net Income | C31: ='Financial Statements'!C24 -> 1182.698 | D31: ='Financial Statements'!D24 -> 1316.524 | E31: ='Financial Statements'!E24 -> 904.076 | F31: ='Financial Statements'!F24 -> 999.779 | G31: ='Financial Statements'!G24 -> 1208.0785 | H31: ='Financial Statements'!H24 -> 1287.7165 | I31: ='Financial Statements'!I24 -> 1373.9473 | J31: ='Financial Statements'!J24 -> 1467.4214 | K31: ='Financial Statements'!K24 -> 1568.8601
B32: Dividends | C32: =-Assumptions!C94 -> -506.232 | D32: =-Assumptions!D94 -> -533.118 | E32: =-Assumptions!E94 -> -556.651 | F32: =-Assumptions!F94 -> -619.86298 | G32: =-Assumptions!G94 -> -752.02889 | H32: =-Assumptions!H94 -> -804.8228 | I32: =-Assumptions!I94 -> -862.15196 | J32: =-Assumptions!J94 -> -924.47551 | K32: =-Assumptions!K94 -> -992.304
B33: Purchase of Stock | C33: =-Assumptions!C100 -> -221.154 | D33: =-Assumptions!D100 -> -259.719 | E33: =-Assumptions!E100 -> -148.914 | F33: =-Assumptions!F100 -> -159.96464 | G33: =-Assumptions!G100 -> -193.29257 | H33: =-Assumptions!H100 -> -206.03464 | I33: =-Assumptions!I100 -> -219.83158 | J33: =-Assumptions!J100 -> -234.78743 | K33: =-Assumptions!K100 -> -251.01761
B34: Ending Retained Earnings | C34: =C30+C31+C32+C33 -> 4541.637 | D34: =D30+D31+D32+D33 -> 5065.324 | E34: =E30+E31+E32+E33 -> 5263.835 | F34: =F30+F31+F32+F33 -> 5483.7864 | G34: =G30+G31+G32+G33 -> 5746.5435 | H34: =H30+H31+H32+H33 -> 6023.4025 | I34: =I30+I31+I32+I33 -> 6315.3663 | J34: =J30+J31+J32+J33 -> 6623.5248 | K34: =K30+K31+K32+K33 -> 6949.0633
B36: TEV/Forward EBITDA Multiple
B37: GPC Entreprise Value | C37: =Comps!D10 -> 23086.493
B38: EBITDA 2025E | C38: =DCF!C17-DCF!C14 -> 1753.3574
B39: Multiple | C39: =C37/C38 -> 13.167021

Sheet DCF
B2: Active Case: | C2: =Summary!C2 -> 1
B3: $ in millions | C3: Projected Years
C5: 46022 | D5: 46387 | E5: 46752 | F5: 47118 | G5: 47483 | H5: 47848 | J5: CAGR
B7: Operating Build: | L7: Terminal Value | O7: Terminal Value | S7: Perpetuity Growth Method
B8: Total Revenue | C8: ='Revenue Build'!F7 -> 24352.186 | D8: ='Revenue Build'!G7 -> 25289.482 | E8: ='Revenue Build'!H7 -> 26304.085 | F8: ='Revenue Build'!I7 -> 27402.221 | G8: ='Revenue Build'!J7 -> 28590.773 | H8: ='Revenue Build'!K7 -> 29877.358 | J8: =(H8/C8)^(1/5)-1 -> 0.041743617 | L8: Perpetuity Growth Method | O8: Exit Multiple Method | T8: Perpetuity Growth Rate
B9: % Growth | C9: ='Revenue Build'!F8 -> 0.036855834 | D9: ='Revenue Build'!G8 -> 0.03848917 | E9: ='Revenue Build'!H8 -> 0.040119578 | F9: ='Revenue Build'!I8 -> 0.041747734 | G9: ='Revenue Build'!J8 -> 0.043374317 | H9: ='Revenue Build'!K8 -> 0.045 | L9: 2030 FCF | M9: =H25 -> 1070.9661 | O9: 2030 EBITDA | P9: =H17+(-H14) -> 3107.2453 | S9: =M20 -> 154.22874 | T9: =U9-0.005 -> 0.015 | U9: =V9-0.005 -> 0.02 | V9: =W9-0.005 -> 0.025 | W9: 0.03 | X9: =W9+0.005 -> 0.035 | Y9: =X9+0.005 -> 0.04 | Z9: =Y9+0.005 -> 0.045
B10: Cost of Goods Sold | C10: =-Assumptions!F8 -> -15463.638 | D10: =-Assumptions!G8 -> -15995.597 | E10: =-Assumptions!H8 -> -16571.573 | F10: =-Assumptions!I8 -> -17194.894 | G10: =-Assumptions!J8 -> -17869.233 | H10: =-Assumptions!K8 -> -18598.655 | L10: Perpetuity Growth Rate | M10: 0.03 | O10: Multiple | P10: =Comps!C19 -> 11 | S10: =S11-0.006 -> 0.058 | T10: 128.02149 | U10: 135.62873 | V10: 144.71751 | W10: 155.76733 | X10: 169.48962 | Y10: 186.9873 | Z10: 210.06695
B11: Gross Profit | C11: =C8+C10 -> 8888.5479 | D11: =D8+D10 -> 9293.8845 | E11: =E8+E10 -> 9732.5114 | F11: =F8+F10 -> 10207.327 | G11: =G8+G10 -> 10721.54 | H11: =H8+H10 -> 11278.703 | J11: =(H11/C11)^(1/5)-1 -> 0.048783065 | L11: Terminal Value | M11: =M9/(WACC!C18-M10) -> 23107.681 | O11: Terminal Value | P11: =P9*P10 -> 34179.698 | S11: =S12-0.006 -> 0.064 | T11: 127.49509 | U11: 135.10233 | V11: 144.19111 | W11: 155.24093 | X11: 168.96323 | Y11: 186.4609 | Z11: 209.54056
B12: Gross Profit Margin | C12: =C11/C8 -> 0.365 | D12: =D11/D8 -> 0.3675 | E12: =E11/E8 -> 0.37 | F12: =F11/F8 -> 0.3725 | G12: =G11/G8 -> 0.375 | H12: =H11/H8 -> 0.3775 | L12: PV of Terminal Value | M12: =M11/(1+WACC!C18)^H26 -> 15848.98 | O12: PV of Terminal Value | P12: =P11/(1+WACC!C18)^H26 -> 23442.999 | S12: =S13-0.006 -> 0.07 | T12: 126.98238 | U12: 134.58962 | V12: 143.6784 | W12: 154.72822 | X12: 168.45051 | Y12: 185.94819 | Z12: 209.02785
B13: SG&A | C13: =-Assumptions!F14 -> -6940.373 | D13: =-Assumptions!G14 -> -7144.2785 | E13: =-Assumptions!H14 -> -7365.1438 | F13: =-Assumptions!I14 -> -7604.1163 | G13: =-Assumptions!J14 -> -7862.4627 | H13: =-Assumptions!K14 -> -8141.5801 | S13: 0.076 | T13: 126.4829 | U13: 134.09014 | V13: 143.17892 | W13: 154.22874 | X13: 167.95103 | Y13: 185.44871 | Z13: 208.52836
B14: D&A | C14: =-Assumptions!F20 -> -426.16326 | D14: =-Assumptions!G20 -> -531.07911 | E14: =-Assumptions!H20 -> -644.45008 | F14: =-Assumptions!I20 -> -767.26218 | G14: =-Assumptions!J20 -> -900.60936 | H14: =-Assumptions!K20 -> -1045.7075 | L14: PV of Projected UFCFs | M14: =SUM(C28:H28) -> 5218.2432 | O14: PV of Projected UFCFs | P14: =SUM(C28:H28) -> 5218.2432 | S14: =S13+0.006 -> 0.082 | T14: 125.99621 | U14: 133.60345 | V14: 142.69223 | W14: 153.74205 | X14: 167.46434 | Y14: 184.96202 | Z14: 208.04167
B15: Provision for Doubtful Accounts | C15: =-Assumptions!F26 -> -24.352186 | D15: =-Assumptions!G26 -> -25.289482 | E15: =-Assumptions!H26 -> -26.304085 | F15: =-Assumptions!I26 -> -27.402221 | G15: =-Assumptions!J26 -> -28.590773 | H15: =-Assumptions!K26 -> -29.877358 | L15: Implied TEV | M15: =M14+M12 -> 21067.223 | O15: Implied TEV | P15: =P14+P12 -> 28661.242 | S15: =S14+0.006 -> 0.088 | T15: 125.52189 | U15: 133.12913 | V15: 142.21791 | W15: 153.26772 | X15: 166.99002 | Y15: 184.4877 | Z15: 207.56735
B16: RX & Other Costs | C16: =-Assumptions!F32 -> -170.4653 | D16: =-Assumptions!G32 -> 0 | E16: =-Assumptions!H32 -> 0 | F16: =-Assumptions!I32 -> 0 | G16: =-Assumptions!J32 -> 0 | H16: =-Assumptions!K32 -> 0 | L16: (-) Total Debt | M16: 6.0861 | O16: (-) Total Debt | P16: 6.0861 | S16: =S15+0.006 -> 0.094 | T16: 125.05953 | U16: 132.66677 | V16: 141.75555 | W16: 152.80537 | X16: 166.52766 | Y16: 184.02534 | Z16: 207.10499
B17: EBIT | C17: =C11+C13+C14+C15+C16 -> 1327.1941 | D17: =D11+D13+D14+D15+D16 -> 1593.2373 | E17: =E11+E13+E14+E15+E16 -> 1696.6135 | F17: =F11+F13+F14+F15+F16 -> 1808.5466 | G17: =G11+G13+G14+G15+G16 -> 1929.8772 | H17: =H11+H13+H14+H15+H16 -> 2061.5377 | J17: =(H17/C17)^(1/5)-1 -> 0.092072235 | L17: (+) Cash | M17: ='Financial Statements'!E30 -> 479.991 | O17: (+) Cash | P17: ='Financial Statements'!E30 -> 479.991
B18: EBIT Margin | C18: =C17/C8 -> 0.0545 | D18: =D17/D8 -> 0.063 | E18: =E17/E8 -> 0.0645 | F18: =F17/F8 -> 0.066 | G18: =G17/G8 -> 0.0675 | H18: =H17/H8 -> 0.069 | L18: Implied Equity Value | M18: =M15-M16+M17 -> 21541.128 | O18: Implied Equity Value | P18: =P15-P16+P17 -> 29135.147
B19: Tax Expense | C19: =-Assumptions!F50 -> -278.71077 | D19: =-Assumptions!G50 -> -334.57984 | E19: =-Assumptions!H50 -> -356.28883 | F19: =-Assumptions!I50 -> -379.79478 | G19: =-Assumptions!J50 -> -405.27421 | H19: =-Assumptions!K50 -> -432.92292 | L19: Diluted Shares Outstanding | M19: 139.67 | O19: Diluted Shares Outstanding | P19: 139.67 | S19: Exit Multiple Method
B20: Effective Tax Rate | C20: =-C19/C17 -> 0.21 | D20: =-D19/D17 -> 0.21 | E20: =-E19/E17 -> 0.21 | F20: =-F19/F17 -> 0.21 | G20: =-G19/G17 -> 0.21 | H20: =-H19/H17 -> 0.21 | L20: Share Price | M20: =M18/M19 -> 154.22874 | O20: Share Price | P20: =P18/P19 -> 208.59989
B21: NOPAT | C21: =C17+C19 -> 1048.4834 | D21: =D17+D19 -> 1258.6575 | E21: =E17+E19 -> 1340.3246 | F21: =F17+F19 -> 1428.7518 | G21: =G17+G19 -> 1524.603 | H21: =H17+H19 -> 1628.6148 | S21: =P20 -> 208.59989 | T21: =U21-0.5 -> 9.5 | U21: =V21-0.5 -> 10 | V21: =W21-0.5 -> 10.5 | W21: 11 | X21: =W21+0.5 -> 11.5 | Y21: =X21+0.5 -> 12 | Z21: =Y21+0.5 -> 12.5
B22: D&A | C22: =Assumptions!F20 -> 426.16326 | D22: =Assumptions!G20 -> 531.07911 | E22: =Assumptions!H20 -> 644.45008 | F22: =Assumptions!I20 -> 767.26218 | G22: =Assumptions!J20 -> 900.60936 | H22: =Assumptions!K20 -> 1045.7075 | L22: Blended Share Price | O22: WACC: | P22: 0.076 | S22: =S23-0.006 -> 0.058 | T22: 187.25044 | U22: 194.87979 | V22: 202.50913 | W22: 210.13848 | X22: 217.76783 | Y22: 225.39717 | Z22: 233.02652
B23: Capex | C23: =-Assumptions!F57 -> -608.80465 | D23: =-Assumptions!G57 -> -758.68445 | E23: =-Assumptions!H57 -> -920.64297 | F23: =-Assumptions!I57 -> -1096.0888 | G23: =-Assumptions!J57 -> -1286.5848 | H23: =-Assumptions!K57 -> -1493.8679 | L23: Perpetuity Growth Method | M23: =M20 -> 154.22874 | S23: =S24-0.006 -> 0.064 | T23: 186.72404 | U23: 194.35339 | V23: 201.98274 | W23: 209.61208 | X23: 217.24143 | Y23: 224.87078 | Z23: 232.50012
B24: Change in NWC | C24: =-'Calculations & Schedules'!F19 -> 348.28002 | D24: =-'Calculations & Schedules'!G19 -> -80.376883 | E24: =-'Calculations & Schedules'!H19 -> -86.664546 | F24: =-'Calculations & Schedules'!I19 -> -93.567938 | G24: =-'Calculations & Schedules'!J19 -> -101.15172 | H24: =-'Calculations & Schedules'!K19 -> -109.48837 | L24: Weight | M24: 0.5 | S24: =S25-0.006 -> 0.07 | T24: 186.21133 | U24: 193.84068 | V24: 201.47003 | W24: 209.09937 | X24: 216.72872 | Y24: 224.35807 | Z24: 231.98741
B25: UFCF | C25: =C21+C22+C23+C24 -> 1214.122 | D25: =D21+D22+D23+D24 -> 950.67528 | E25: =E21+E22+E23+E24 -> 977.46721 | F25: =F21+F22+F23+F24 -> 1006.3572 | G25: =G21+G22+G23+G24 -> 1037.4758 | H25: =H21+H22+H23+H24 -> 1070.9661 | L25: Exit Multiple Method | M25: =P20 -> 208.59989 | S25: 0.076 | T25: 185.71185 | U25: 193.3412 | V25: 200.97054 | W25: 208.59989 | X25: 216.22924 | Y25: 223.85858 | Z25: 231.48793
B26: Discount Period | C26: =YEARFRAC(Cover!B18,C5)/2 -> 0.125 | D26: =C26+1 -> 1.125 | E26: =D26+1 -> 2.125 | F26: =E26+1 -> 3.125 | G26: =F26+1 -> 4.125 | H26: =G26+1 -> 5.125 | L26: Weight | M26: 0.5 | S26: =S25+0.006 -> 0.082 | T26: 185.22516 | U26: 192.85451 | V26: 200.48385 | W26: 208.1132 | X26: 215.74255 | Y26: 223.37189 | Z26: 231.00124
B27: Discount Factor | C27: =1/(1+$P$22)^C26 -> 0.99088548 | D27: =1/(1+$P$22)^D26 -> 0.92089729 | E27: =1/(1+$P$22)^E26 -> 0.8558525 | F27: =1/(1+$P$22)^F26 -> 0.79540195 | G27: =1/(1+$P$22)^G26 -> 0.73922114 | H27: =1/(1+$P$22)^H26 -> 0.6870085 | L27: Blended Share Price | M27: =(M23*M24)+(M25*M26) -> 181.41431 | S27: =S26+0.006 -> 0.088 | T27: 184.75084 | U27: 192.38018 | V27: 200.00953 | W27: 207.63888 | X27: 215.26822 | Y27: 222.89757 | Z27: 230.52692
B28: PV of UFCF | C28: =C25*C27 -> 1203.0559 | D28: =D25*D27 -> 875.47429 | E28: =E25*E27 -> 836.56775 | F28: =F25*F27 -> 800.45848 | G28: =G25*G27 -> 766.92407 | H28: =H25*H27 -> 735.76278 | L28: Implied Upside | M28: =(M27-Summary!E8)/Summary!E8 -> 0.31297905 | S28: =S27+0.006 -> 0.094 | T28: 184.28848 | U28: 191.91782 | V28: 199.54717 | W28: 207.17652 | X28: 214.80586 | Y28: 222.43521 | Z28: 230.06456

Sheet WACC
B2: Active Case: | C2: =Summary!C2 -> 1
B4: Weighted Average Cost of Capital
B5: Market Risk Premium | C5: 0.0583
B6: Beta | C6: 0.782
B7: Risk Free Rate | C7: 0.04171
B8: Cost of Equity | C8: =C5*C6+C7 -> 0.0873006
B10: Debt Rate | C10: 0.0582
B11: Tax Rate | C11: 0.21
B12: Cost of Debt | C12: =C10*(1-C11) -> 0.045978
B14: Total Equity ($M) | C14: 16873.28
B15: Total Debt ($M) | C15: 6086.1
B16: Equity / Total Capitalizaiton | C16: =C14/(C14+C15) -> 0.7349188
B17: Debt / Total Capitalization | C17: =C15/(C14+C15) -> 0.2650812
B18: WACC | C18: =(C8*C16)+(C12*C17) -> 0.076346756

Sheet Comps
B2: Active Case: | C2: =Summary!C2 -> 1
B3: $ in millions
B5: Company | C5: Market Cap | D5: Enterprise Value | E5: Gross Margin (LTM) | F5: EBITDA Margin (LTM) | G5: EV/EBITDA (LTM) | H5: EV/EBITDA (NTM) | I5: EV/Revenue (LTM) | J5: EV/Revenue (NTM) | K5: EPS (LTM) | L5: Forward P/E
B6: Advance AutoParts, Inc. (NYSE:AAP) | C6: 3662.081 | D6: 6057.081 | E6: 0.42 | F6: 0.03 | G6: 6 | H6: 13 | I6: 1 | J6: 1 | K6: -6 | L6: 23
B7: Autozone, Inc. (NYSE:AZO) | C7: 69607.872 | D7: 81629.72 | E7: 0.53 | F7: 0.22 | G7: 18 | H7: 18 | I7: 4 | J7: 4 | K7: 149 | L7: 25
B8: LKQ Corporation (NasdaqGS:LKQ) | C8: 7819.14 | D8: 13476.14 | E8: 0.39 | F8: 0.12 | G8: 6 | H8: 9 | I8: 1 | J8: 1 | K8: 3 | L8: 10
B9: O'Reilly Automotive, Inc. (NasdaqGS:ORLY) | C9: 87793.951 | D9: 95844.117 | E9: 0.51 | F9: 0.22 | G9: 22 | H9: 24 | I9: 5 | J9: 5 | K9: 3 | L9: 32
B10: Genuine Parts Company (NYSE:GPC) | C10: 19279.583 | D10: =Summary!E12 -> 23086.493 | E10: 0.37 | F10: 0.08 | G10: 11 | H10: 12 | I10: 1 | J10: 1 | K10: 6 | L10: 17
B12: Low | C12: =MIN(C6:C10) -> 3662.081 | D12: =MIN(D6:D10) -> 6057.081 | E12: =MIN(E6:E10) -> 0.37 | F12: =MIN(F6:F10) -> 0.03 | G12: =MIN(G6:G10) -> 6 | H12: =MIN(H6:H10) -> 9 | I12: =MIN(I6:I10) -> 1 | J12: =MIN(J6:J10) -> 1 | ... L12: =MIN(L6:L10) -> 10
B13: 25th Percentile | C13: =_xlfn.PERCENTILE.INC((C6:C10), 0.25) -> 7819.14 | D13: =_xlfn.PERCENTILE.INC((D6:D10), 0.25) -> 13476.14 | E13: =_xlfn.PERCENTILE.INC((E6:E10), 0.25) -> 0.39 | F13: =_xlfn.PERCENTILE.INC((F6:F10), 0.25) -> 0.08 | G13: =_xlfn.PERCENTILE.INC((G6:G10), 0.25) -> 6 | H13: =_xlfn.PERCENTILE.INC((H6:H10), 0.25) -> 12 | I13: =_xlfn.PERCENTILE.INC((I6:I10), 0.25) -> 1 | J13: =_xlfn.PERCENTILE.INC((J6:J10), 0.25) -> 1 | ... L13: =_xlfn.PERCENTILE.INC((L6:L10), 0.25) -> 17
B14: Mean | C14: =AVERAGE(C6:C10) -> 37632.525 | D14: =AVERAGE(D6:D10) -> 44018.71 | E14: =AVERAGE(E6:E10) -> 0.444 | F14: =AVERAGE(F6:F10) -> 0.134 | G14: =AVERAGE(G6:G10) -> 12.6 | H14: =AVERAGE(H6:H10) -> 15.2 | I14: =AVERAGE(I6:I10) -> 2.4 | J14: =AVERAGE(J6:J10) -> 2.4 | ... L14: =AVERAGE(L6:L10) -> 21.4
B15: Median | C15: =MEDIAN(C6:C10) -> 19279.583 | D15: =MEDIAN(D6:D10) -> 23086.493 | E15: =MEDIAN(E6:E10) -> 0.42 | F15: =MEDIAN(F6:F10) -> 0.12 | G15: =MEDIAN(G6:G10) -> 11 | H15: =MEDIAN(H6:H10) -> 13 | I15: =MEDIAN(I6:I10) -> 1 | J15: =MEDIAN(J6:J10) -> 1 | ... L15: =MEDIAN(L6:L10) -> 23
B16: 75th Percentile | C16: =_xlfn.PERCENTILE.INC((C6:C10), 0.75) -> 69607.872 | D16: =_xlfn.PERCENTILE.INC((D6:D10), 0.75) -> 81629.72 | E16: =_xlfn.PERCENTILE.INC((E6:E10), 0.75) -> 0.51 | F16: =_xlfn.PERCENTILE.INC((F6:F10), 0.75) -> 0.22 | G16: =_xlfn.PERCENTILE.INC((G6:G10), 0.75) -> 18 | H16: =_xlfn.PERCENTILE.INC((H6:H10), 0.75) -> 18 | I16: =_xlfn.PERCENTILE.INC((I6:I10), 0.75) -> 4 | J16: =_xlfn.PERCENTILE.INC((J6:J10), 0.75) -> 4 | ... L16: =_xlfn.PERCENTILE.INC((L6:L10), 0.75) -> 25
B17: High | C17: =MAX(C6:C10) -> 87793.951 | D17: =MAX(D6:D10) -> 95844.117 | E17: =MAX(E6:E10) -> 0.53 | F17: =MAX(F6:F10) -> 0.22 | G17: =MAX(G6:G10) -> 22 | H17: =MAX(H6:H10) -> 24 | I17: =MAX(I6:I10) -> 5 | J17: =MAX(J6:J10) -> 5 | ... L17: =MAX(L6:L10) -> 32
B19: Selected Multiple: EV/EBITDA (NTM) | C19: =G15 -> 11

Sheet Base Case Revenue Projection
D3: Forecasted Years
B5: $ in millions | D5: 2025E | E5: 2026E | F5: 2027E | G5: 2028E | H5: 2029E | I5: 2030E | K5: CAGR
B7: Build
B8: Total Revenue | D8: 24352186 | E8: 25289482 | F8: 26304085 | G8: 27402221 | H8: 28590773 | I8: 29877358 | K8: =(I8/D8)^(1/(6-1))-1 -> 0.041743617
B9: % Growth | D9: 0.036855834 | E9: 0.03848917 | F9: 0.040119578 | G9: 0.041747734 | H9: 0.043374317 | I9: 0.045
B10: COGS | D10: -15463638 | E10: -15995597 | F10: -16571573 | G10: -17194894 | H10: -17869233 | I10: -18598655
B11: Gross Profit | D11: 8888547.9 | E11: 9293884.5 | F11: 9732511.4 | G11: 10207327 | H11: 10721540 | I11: 11278703 | K11: =(I11/D11)^(1/(6-1))-1 -> 0.048783065
B12: Gross Profit Margin | D12: 0.365 | E12: 0.3675 | F12: 0.37 | G12: 0.3725 | H12: 0.375 | I12: 0.3775
B13: SG&A | D13: -6940373 | E13: -7144278.5 | F13: -7365143.8 | G13: -7604116.3 | H13: -7862462.7 | I13: -8141580.1
B14: Provision for Bad Debt | D14: -24352.186 | E14: -25289.482 | F14: -26304.085 | G14: -27402.221 | H14: -28590.773 | I14: -29877.358
B15: RX & Other Costs | D15: -170465.3 | E15: 0 | F15: 0 | G15: 0 | H15: 0 | I15: 0
B16: EBITDA | D16: =D19-D18 -> 1753357.4 | E16: =E19-E18 -> 2124316.4 | F16: =F19-F18 -> 2341063.5 | G16: =G19-G18 -> 2575808.8 | H16: =H19-H18 -> 2830486.6 | I16: =I19-I18 -> 3107245.3 | K16: =(I16/D16)^(1/(6-1))-1 -> 0.12124628
B17: EBITDA Margin | D17: =D16/D8 -> 0.072 | E17: =E16/E8 -> 0.084 | F17: =F16/F8 -> 0.089 | G17: =G16/G8 -> 0.094 | H17: =H16/H8 -> 0.099 | I17: =I16/I8 -> 0.104
B18: D&A | D18: -426163.26 | E18: -531079.11 | F18: -644450.08 | G18: -767262.18 | H18: -900609.36 | I18: -1045707.5
B19: EBIT | D19: 1327194.1 | E19: 1593237.3 | F19: 1696613.5 | G19: 1808546.6 | H19: 1929877.2 | I19: 2061537.7 | K19: =(I19/D19)^(1/(6-1))-1 -> 0.092072235
B20: EBIT Margin | D20: 0.0545 | E20: 0.063 | F20: 0.0645 | G20: 0.066 | H20: 0.0675 | I20: 0.069
B21: Tax Expense | D21: -278710.77 | E21: -334579.84 | F21: -356288.83 | G21: -379794.78 | H21: -405274.21 | I21: -432922.92
B22: Effective Tax Rate | D22: 0.21 | E22: 0.21 | F22: 0.21 | G22: 0.21 | H22: 0.21 | I22: 0.21
B23: NOPAT | D23: 1048483.4 | E23: 1258657.5 | F23: 1340324.6 | G23: 1428751.8 | H23: 1524603 | I23: 1628614.8 | K23: =(I23/D23)^(1/(6-1))-1 -> 0.092072235
B24: Capex | D24: -608804.65 | E24: -758684.45 | F24: -920642.97 | G24: -1096088.8 | H24: -1286584.8 | I24: -1493867.9
B25: Change in NWC | D25: 348280.02 | E25: -80376.883 | F25: -86664.546 | G25: -93567.938 | H25: -101151.72 | I25: -109488.37
B26: UFCF | D26: 1214122 | E26: 950675.28 | F26: 977467.21 | G26: 1006357.2 | H26: 1037475.8 | I26: 1070966.1
B27: Discount Period | D27: 0.125 | E27: 1.125 | F27: 2.125 | G27: 3.125 | H27: 4.125 | I27: 5.125 | K27: =(I26/D26)^(1/(6-1))-1 -> -0.024779829
B28: Discount Factor | D28: 0.99088548 | E28: 0.92089729 | F28: 0.8558525 | G28: 0.79540195 | H28: 0.73922114 | I28: 0.6870085
B29: PV of UFCF | D29: =D26*D28 -> 1203055.9 | E29: =E26*E28 -> 875474.29 | F29: =F26*F28 -> 836567.75 | G29: =G26*G28 -> 800458.48 | H29: =H26*H28 -> 766924.07 | I29: =I26*I28 -> 735762.78

Sheet Terminal Values (Base)
B3: Terminal Value | E3: Terminal Value
B4: Perpetuity Growth Method | E4: Exit Multiple Method
B5: 2030 FCF | C5: 1070966.1 | E5: 2030 EBITDA | F5: 3107245.3
B6: Perpetuity Growth Rate | C6: 0.03 | E6: Multiple | F6: 11
B7: Terminal Value | C7: 23107681 | E7: Terminal Value | F7: 34179698
B8: PV of Terminal Value | C8: 15848980 | E8: PV of Terminal Value | F8: 23442999
B10: PV of Projected UFCFs | C10: 5218243.2 | E10: PV of Projected UFCFs | F10: 5218243.2
B11: PV of Terminal Value | C11: 15848980 | E11: PV of Terminal Value | F11: 23442999
B12: Implied TEV | C12: 21067223 | E12: Implied TEV | F12: 28661242
B13: (-) Total Debt | C13: 6086.1 | E13: (-) Total Debt | F13: 6086.1
B14: (+) Cash | C14: 479991 | E14: (+) Cash | F14: 479991
B15: Implied Equity Value | C15: 21541128 | E15: Implied Equity Value | F15: 29135147
B16: Diluted Shares Outstanding | C16: 139670 | E16: Diluted Shares Outstanding | F16: 139670
B17: Share Price | C17: 154.22874 | E17: Share Price | F17: 208.59989
B19: Blended Share Price | E19: WACC: | F19: 0.076
B20: Perpetuity Growth Method | C20: =C17 -> 154.22874
B21: Weight | C21: 0.5
B22: Exit Multiple Method | C22: =F17 -> 208.59989
B23: Weight | C23: 0.5
B24: Blended Share Price | C24: =C20*C21+C22*C23 -> 181.41431
B25: Implied Upside | C25: 0.31297905

Sheet Bear Case Projection
D3: Forecasted Years
B5: $ in millions | D5: 2025E | E5: 2026E | F5: 2027E | G5: 2028E | H5: 2029E | I5: 2030E | K5: CAGR
B7: Build | M7: Terminal Value | P7: Terminal Value
B8: Total Revenue | D8: 24117320 | E8: 24725893 | F8: 25309812 | G8: 25866683 | H8: 26394207 | I8: 26890201 | K8: =(I8/D8)^(1/(6-1))-1 -> 0.022004949 | M8: Perpetuity Growth Method | P8: Exit Multiple Method
B9: % Growth | D9: 0.026855834 | E9: 0.02523382 | F9: 0.023615697 | G9: 0.022002172 | H9: 0.02039396 | I9: 0.018791785 | M9: 2030 FCF | N9: 690232.98 | P9: 2030 EBITDA | Q9: 2258776.9
B10: COGS | D10: -15555672 | E10: -15886386 | F10: -16198279 | G10: -16490010 | H10: -16760321 | I10: -17008052 | M10: Perpetuity Growth Rate | N10: 0.03 | P10: Multiple | Q10: 11
B11: Gross Profit | D11: 8561648.7 | E11: 8839506.6 | F11: 9111532.2 | G11: 9376672.4 | H11: 9633885.4 | I11: 9882148.8 | K11: =(I11/D11)^(1/(6-1))-1 -> 0.029102887 | M11: Terminal Value | N11: 14892800 | P11: Terminal Value | Q11: 24846546
B12: Gross Profit Margin | D12: 0.355 | E12: 0.3575 | F12: 0.36 | G12: 0.3625 | H12: 0.365 | I12: 0.3675 | M12: PV of Terminal Value | N12: 10214599 | P12: PV of Terminal Value | Q12: 17041623
B13: SG&A | D13: -7114609.5 | E13: -7232323.6 | F13: -7339845.4 | G13: -7436671.2 | H13: -7522348.9 | I13: -7596481.7
B14: Provision for Bad Debt | D14: -24117.32 | E14: -24725.893 | F14: -25309.812 | G14: -25866.683 | H14: -26394.207 | I14: -26890.201 | M14: PV of Projected UFCFs | N14: 3621671.1 | P14: PV of Projected UFCFs | Q14: 3621671.1
B15: RX & Other Costs | D15: -192938.56 | E15: 0 | F15: 0 | G15: 0 | H15: 0 | I15: 0 | M15: PV of Terminal Value | N15: 10214599 | P15: PV of Terminal Value | Q15: 17041623
B16: EBITDA | D16: =D19-D18 -> 1229983.3 | E16: =E19-E18 -> 1582457.1 | F16: =F19-F18 -> 1746377 | G16: =G19-G18 -> 1914134.5 | H16: =H19-H18 -> 2085142.3 | I16: =I19-I18 -> 2258776.9 | K16: =(I16/D16)^(1/(6-1))-1 -> 0.12926228 | M16: Implied TEV | N16: 13836270 | P16: Implied TEV | Q16: 20663294
B17: EBITDA Margin | D17: =D16/D8 -> 0.051 | E17: =E16/E8 -> 0.064 | F17: =F16/F8 -> 0.069 | G17: =G16/G8 -> 0.074 | H17: =H16/H8 -> 0.079 | I17: =I16/I8 -> 0.084 | M17: (-) Total Debt | N17: 6086.1 | P17: (-) Total Debt | Q17: 6086.1
B18: D&A | D18: -340054.22 | E18: -435793.86 | F18: -535302.52 | G18: -638260.39 | H18: -744316.63 | I18: -853091.62 | M18: (+) Cash | N18: 479991 | P18: (+) Cash | Q18: 479991
B19: EBIT | D19: 889929.12 | E19: 1146663.3 | F19: 1211074.5 | G19: 1275874.1 | H19: 1340825.7 | I19: 1405685.3 | K19: =(I19/D19)^(1/(6-1))-1 -> 0.095737522 | M19: Implied Equity Value | N19: 14310175 | P19: Implied Equity Value | Q19: 21137199
B20: EBIT Margin | D20: 0.0369 | E20: 0.046375 | F20: 0.04785 | G20: 0.049325 | H20: 0.0508 | I20: 0.052275 | M20: DSO | N20: 139670 | P20: DSO | Q20: 139670
B21: Tax Expense | D21: -186885.12 | E21: -240799.29 | F21: -254325.64 | G21: -267933.56 | H21: -281573.4 | I21: -295193.9 | M21: Share Price | N21: 102.45704 | P21: Share Price | Q21: 151.33672
B22: Effective Tax Rate | D22: 0.21 | E22: 0.21 | F22: 0.21 | G22: 0.21 | H22: 0.21 | I22: 0.21
B23: NOPAT | D23: 703044.01 | E23: 905863.98 | F23: 956748.85 | G23: 1007940.6 | H23: 1059252.3 | I23: 1110491.3 | K23: =(I23/D23)^(1/(6-1))-1 -> 0.095737522 | M23: Blended Share Price | P23: WACC: | Q23: 0.076
B24: Capex | D24: -482346.41 | E24: -618147.31 | F24: -759294.35 | G24: -905333.89 | H24: -1055768.3 | I24: -1210059 | M24: PGM | N24: =N21 -> 102.45704
B25: Change in NWC | D25: 371670.95 | E25: -63922.827 | F25: -64139.204 | G25: -64110.078 | H25: -63828.881 | I25: -63290.949 | M25: Weight | N25: 0.5
B26: UFCF | D26: 932422.77 | E26: 659587.7 | F26: 668617.81 | G26: 676756.98 | H26: 683971.78 | I26: 690232.98 | M26: Exit Multiple Method | N26: =Q21 -> 151.33672
B27: Discount Period | D27: 0.125 | E27: 1.125 | F27: 2.125 | G27: 3.125 | H27: 4.125 | I27: 5.125 | K27: =(I26/D26)^(1/(6-1))-1 -> -0.058378063 | M27: Weight | N27: 0.5
B28: Discount Factor | D28: 0.99088548 | E28: 0.92089729 | F28: 0.8558525 | G28: 0.79540195 | H28: 0.73922114 | I28: 0.6870085 | M28: Blended Share Price | N28: =N24*N25+N26*N27 -> 126.89688
